<mujoco model="base">
  <compiler angle="radian" autolimits="true"/>
  <option impratio="20" density="1.2" viscosity="2e-05" integrator="RK4" cone="elliptic" solver="PGS" iterations="50"/>
  <size/>
  <visual>
    <map znear="0.001"/>
  </visual>
  <default/>
  <asset>
    <texture type="skybox" builtin="gradient" rgb1="0.9 0.9 1" rgb2="0.2 0.3 0.4" width="256" height="1536"/>
    <texture type="2d" name="texplane" file="models/textures/light-gray-floor-tile.png"/>
    <texture type="2d" name="tex-light-gray-plaster" file="models/textures/light-gray-plaster.png"/>
    <texture type="cube" name="Door_light-wood" file="models/objects/../textures/light-wood.png"/>
    <texture type="cube" name="Door_metal" file="models/objects/../textures/steel-brushed.png"/>
    <texture type="cube" name="Door_glass" file="models/objects/../textures/navy.png"/>
    <texture type="cube" name="wall0_white-bricks" file="models/objects/../textures/white-bricks.png"/>
    <texture type="cube" name="wall1_white-bricks" file="models/objects/../textures/white-bricks.png"/>
    <material name="robot0_metal" rgba="0.58 0.58 0.58 1"/>
    <material name="robot0_black" rgba="0.149 0.149 0.149 1"/>
    <material name="robot0_transparent" rgba="1 1 1 0"/>
    <material name="gripperright_metal" rgba="0.58 0.58 0.58 1"/>
    <material name="gripperright_black" rgba="0.149 0.149 0.149 1"/>
    <material name="gripperright_gray" rgba="0.4627 0.4627 0.4627 1"/>
    <material name="gripperright_white" rgba="0.9 0.9 0.9 1"/>
    <material name="gripperright_silicone" rgba="0.1882 0.1882 0.1882 1"/>
    <material name="gripperright_tendon_line" rgba="0.95 0.3 0.3 0"/>
    <material name="gripperright_tendon_site" rgba="0.1882 0.1882 0.1882 0"/>
    <material name="gripperleft_metal" rgba="0.58 0.58 0.58 1"/>
    <material name="gripperleft_black" rgba="0.149 0.149 0.149 1"/>
    <material name="gripperleft_gray" rgba="0.4627 0.4627 0.4627 1"/>
    <material name="gripperleft_white" rgba="0.9 0.9 0.9 1"/>
    <material name="gripperleft_silicone" rgba="0.1882 0.1882 0.1882 1"/>
    <material name="gripperleft_tendon_line" rgba="0.95 0.3 0.3 0"/>
    <material name="gripperleft_tendon_site" rgba="0.1882 0.1882 0.1882 0"/>
    <material name="floorplane" texture="texplane" texuniform="true" texrepeat="2 2" specular="0" shininess="0" reflectance="0.01"/>
    <material name="walls_mat" texture="tex-light-gray-plaster" texuniform="true" texrepeat="3 3" specular="0.1" shininess="0.1"/>
    <material name="Door_MatLightWood" texture="Door_light-wood" texrepeat="3 3" specular="0.4" shininess="0.1"/>
    <material name="Door_MatBright" texture="Door_metal" specular="1" shininess="0.3" rgba="0.7 0.7 0.7 1"/>
    <material name="Door_MatMedium" texture="Door_metal" specular="0.2" shininess="0.3" rgba="0.4 0.4 0.4 1"/>
    <material name="Door_MatDark" texture="Door_metal" specular="0.2" shininess="0.3" rgba="0.1 0.1 0.1 1"/>
    <material name="Door_MatGlass" texture="Door_glass" specular="1" shininess="0.3"/>
    <material name="wall0_MatWhiteBricks" texture="wall0_white-bricks" texrepeat="3 3" specular="0.4" shininess="0.1"/>
    <material name="wall1_MatWhiteBricks" texture="wall1_white-bricks" texrepeat="3 3" specular="0.4" shininess="0.1"/>
    <mesh name="robot0_mesh_base_viz" file="models/robots/draco3/meshes/torso_link.stl"/>
    <mesh name="robot0_mesh_base_col" file="models/robots/draco3/meshes/torso_link.stl"/>
    <mesh name="robot0_mesh_head_viz" file="models/robots/draco3/meshes/neck_pitch_link.stl"/>
    <mesh name="robot0_mesh_left_S0_viz" file="models/robots/draco3/meshes/l_shoulder_fe_link.stl"/>
    <mesh name="robot0_mesh_left_S1_viz" file="models/robots/draco3/meshes/l_shoulder_aa_link.stl"/>
    <mesh name="robot0_mesh_left_S2_viz" file="models/robots/draco3/meshes/l_shoulder_ie_link.stl"/>
    <mesh name="robot0_mesh_left_E0_viz" file="models/robots/draco3/meshes/l_elbow_fe_link.stl"/>
    <mesh name="robot0_mesh_left_W0_viz" file="models/robots/draco3/meshes/l_wrist_ps_link.stl"/>
    <mesh name="robot0_mesh_left_W2_viz" file="models/robots/draco3/meshes/l_sake_gripper_mount.stl"/>
    <mesh name="robot0_mesh_right_S0_viz" file="models/robots/draco3/meshes/r_shoulder_fe_link.stl"/>
    <mesh name="robot0_mesh_right_S1_viz" file="models/robots/draco3/meshes/r_shoulder_aa_link.stl"/>
    <mesh name="robot0_mesh_right_S2_viz" file="models/robots/draco3/meshes/r_shoulder_ie_link.stl"/>
    <mesh name="robot0_mesh_right_E0_viz" file="models/robots/draco3/meshes/r_elbow_fe_link.stl"/>
    <mesh name="robot0_mesh_right_W0_viz" file="models/robots/draco3/meshes/r_wrist_ps_link.stl"/>
    <mesh name="robot0_mesh_right_W2_viz" file="models/robots/draco3/meshes/r_sake_gripper_mount.stl"/>
    <mesh name="robot0_mesh_left_H0_viz" file="models/robots/draco3/meshes/l_hip_ie_link.stl"/>
    <mesh name="robot0_mesh_left_H1_viz" file="models/robots/draco3/meshes/l_hip_aa_link.stl"/>
    <mesh name="robot0_mesh_left_H2_viz" file="models/robots/draco3/meshes/l_hip_fe_link.stl"/>
    <mesh name="robot0_mesh_left_N0_viz" file="models/robots/draco3/meshes/l_knee_fe_lp.stl"/>
    <mesh name="robot0_mesh_left_N1_viz" file="models/robots/draco3/meshes/l_knee_adj_link.stl"/>
    <mesh name="robot0_mesh_left_N2_viz" file="models/robots/draco3/meshes/l_knee_fe_ld.stl"/>
    <mesh name="robot0_mesh_left_A0_viz" file="models/robots/draco3/meshes/l_ankle_fe_link.stl"/>
    <mesh name="robot0_mesh_left_A1_viz" file="models/robots/draco3/meshes/l_ankle_ie_link.stl"/>
    <mesh name="robot0_mesh_right_H0_viz" file="models/robots/draco3/meshes/r_hip_ie_link.stl"/>
    <mesh name="robot0_mesh_right_H1_viz" file="models/robots/draco3/meshes/r_hip_aa_link.stl"/>
    <mesh name="robot0_mesh_right_H2_viz" file="models/robots/draco3/meshes/r_hip_fe_link.stl"/>
    <mesh name="robot0_mesh_right_N0_viz" file="models/robots/draco3/meshes/r_knee_fe_lp.stl"/>
    <mesh name="robot0_mesh_right_N1_viz" file="models/robots/draco3/meshes/r_knee_adj_link.stl"/>
    <mesh name="robot0_mesh_right_N2_viz" file="models/robots/draco3/meshes/r_knee_fe_ld.stl"/>
    <mesh name="robot0_mesh_right_A0_viz" file="models/robots/draco3/meshes/r_ankle_fe_link.stl"/>
    <mesh name="robot0_mesh_right_A1_viz" file="models/robots/draco3/meshes/r_ankle_ie_link.stl"/>
    <mesh name="gripperright_mesh_finger1" file="models/grippers/sake_ezgripper/meshes/ezgripper_gen2/SAKE_Finger_L1_Gen2.stl"/>
    <mesh name="gripperright_mesh_finger2" file="models/grippers/sake_ezgripper/meshes/ezgripper_gen2/SAKE_Finger_L2_Gen2.stl"/>
    <mesh name="gripperright_mesh_palm_dual" file="models/grippers/sake_ezgripper/meshes/ezgripper_gen2/SAKE_Palm_Dual_Gen2.stl"/>
    <mesh name="gripperleft_mesh_finger1" file="models/grippers/sake_ezgripper/meshes/ezgripper_gen2/SAKE_Finger_L1_Gen2.stl"/>
    <mesh name="gripperleft_mesh_finger2" file="models/grippers/sake_ezgripper/meshes/ezgripper_gen2/SAKE_Finger_L2_Gen2.stl"/>
    <mesh name="gripperleft_mesh_palm_dual" file="models/grippers/sake_ezgripper/meshes/ezgripper_gen2/SAKE_Palm_Dual_Gen2.stl"/>
  </asset>
  <worldbody>
    <geom name="ground" size="3.5 4 0.01" pos="-0.3 0 -0.1" quat="0 0 0 1" type="box" conaffinity="15" margin="-0.005" rgba="0 0 0 0"/>
    <geom name="floor" size="3.5 4 0.01" pos="-0.3 0 -0.08" type="plane" group="1" material="floorplane"/>
    <geom name="ceiling" size="7 7 0.01" pos="-0.3 0 3.2" quat="0 0 0 1" type="box" conaffinity="15" margin="-0.005" material="walls_mat"/>
    <geom name="wall_leftcorner_visual" size="1.06 3.2 0.01" pos="-1.25 2.25 1.5" quat="0.653281 0.653281 0.270598 0.270598" type="box" contype="15" conaffinity="15" group="1" material="walls_mat"/>
    <geom name="wall_rightcorner_visual" size="1.06 3.2 0.01" pos="-1.25 -2.25 1.5" quat="0.653281 0.653281 -0.270598 -0.270598" type="box" contype="15" conaffinity="15" group="1" material="walls_mat"/>
    <geom name="wall_left_visual" size="1.75 3.2 0.01" pos="1.25 3 1.5" quat="0.707107 0.707107 0 0" type="box" contype="15" conaffinity="15" group="1" material="walls_mat"/>
    <geom name="wall_right_visual" size="1.75 3.2 0.01" pos="1.25 -3 1.5" quat="0.707107 -0.707107 0 0" type="box" contype="15" conaffinity="15" group="1" material="walls_mat"/>
    <geom name="wall_rear_visual" size="1.5 3.2 0.01" pos="-2 0 1.5" quat="0.5 0.5 0.5 0.5" type="box" contype="15" conaffinity="15" group="1" material="walls_mat"/>
    <geom name="wall_front_visual" size="3 3.2 0.01" pos="3 0 1.5" quat="0.5 0.5 -0.5 -0.5" type="box" contype="15" conaffinity="15" group="1" material="walls_mat"/>
    <camera name="envview" pos="-2 0 0.75" quat="0.5 -0.5 -0.5 0.5" fovy="89"/>
    <camera name="backview" pos="-2 0 1.2" quat="0.5 -0.5 -0.5 0.5" fovy="120"/>
    <camera name="testview" pos="1.5 0 1" quat="0.5 -0.5 0.5 -0.5"/>
    <camera name="upview" pos="-1 0 2" quat="0.653281 -0.270598 -0.270598 0.653281"/>
    <camera name="kitchenview" pos="1.2 0 1" quat="0.5 -0.5 0.5 -0.5"/>
    <camera name="objectview" pos="0.5 0 3" quat="0.707107 0 0 0.707107"/>
    <camera name="door_testview" pos="3 0 1.1" quat="0.5 -0.5 0.5 -0.5"/>
    <camera name="door_topview" pos="2.2 0 2" quat="0.707107 0 0 0.707107"/>
    <camera name="topview" pos="1 0 2.2" quat="0.707107 0 0 0.707107"/>
    <camera name="frontview" pos="2 0 1.45" quat="0.560842 0.430646 0.430646 0.560842" fovy="120"/>
    <camera name="birdview" pos="-0.2 0 3" quat="0.707107 0 0 0.707107" fovy="120"/>
    <camera name="agentview" pos="0.5 0 1.35" quat="0.653098 0.271041 0.271041 0.653098"/>
    <camera name="sideview" pos="-0.0565177 1.27612 1.48796" quat="0.00990507 0.00687796 0.591223 0.806418"/>
    <light pos="1 1 1.5" dir="-0.19245 -0.19245 -0.96225" directional="true" castshadow="false"/>
    <body name="robot0_base" pos="0 0 1">
      <inertial pos="-0.0310745 -0.000497416 0.137484" quat="0.992104 -0.00586533 -0.0952931 0.0813332" mass="6.41443" diaginertia="0.176721 0.175645 0.0311132"/>
      <joint name="robot0_root" type="free" frictionloss="0.1"/>
      <geom name="robot0_geom_base_viz" type="mesh" contype="0" conaffinity="0" group="1" margin="0.001" material="robot0_metal" mesh="robot0_mesh_base_viz"/>
      <body name="robot0_base_com" pos="0 0 0.087484"/>
      <body name="robot0_link_right_S0" pos="-0.05 -0.156 0.2625" quat="0.965926 -0.258819 0 0">
        <inertial pos="-0.0825089 0.0272215 6.40505e-05" quat="0.735106 0.671185 -0.0753307 -0.0587812" mass="1.02127" diaginertia="0.00303897 0.00199923 0.0019618"/>
        <joint name="robot0_joint_right_S0" pos="0 0 0" axis="0 1 0" range="-2.26893 0.698132" armature="0.01" frictionloss="0.1"/>
        <geom name="robot0_geom_right_S0_viz" pos="0.05 0.27 -0.15" quat="0.965926 0.258819 0 0" type="mesh" contype="0" conaffinity="0" group="1" margin="0.001" material="robot0_metal" mesh="robot0_mesh_right_S0_viz"/>
        <body name="robot0_link_right_S1" pos="0 0 0" quat="0.965926 0.258819 0 0">
          <inertial pos="0.0189446 0.000135529 0.00688183" quat="0.00894532 0.674228 0.00366258 0.73846" mass="0.880498" diaginertia="0.00225176 0.00190046 0.00103185"/>
          <joint name="robot0_joint_right_S1" pos="0 0 0" axis="1 0 0" range="-2.0944 0" armature="0.01" frictionloss="0.1"/>
          <geom name="robot0_geom_right_S1_viz" type="mesh" contype="0" conaffinity="0" group="1" margin="0.001" material="robot0_black" mesh="robot0_mesh_right_S1_viz"/>
          <body name="robot0_link_right_S2" pos="0 0 0">
            <inertial pos="-0.00401807 -0.029987 -0.137263" mass="1.21235" diaginertia="0.00490878 0.00459797 0.00207282"/>
            <joint name="robot0_joint_right_S2" pos="0 0 0" axis="0 0 1" range="-1.48353 1.48353" armature="0.01" frictionloss="0.1"/>
            <geom name="robot0_geom_right_S2_viz" pos="0.05 0.15 -0.26" type="mesh" contype="0" conaffinity="0" group="1" margin="0.001" material="robot0_metal" mesh="robot0_mesh_right_S2_viz"/>
            <body name="robot0_link_right_E0" pos="0 0 -0.25">
              <inertial pos="-0.0190443 0 -0.0633779" quat="0.663353 0.244703 0.24453 0.663542" mass="0.989887" diaginertia="0.00297439 0.00246882 0.00183915"/>
              <joint name="robot0_joint_right_E0" pos="0 0 0" axis="0 1 0" range="-2.0944 0.0872665" armature="0.01" frictionloss="0.1"/>
              <geom name="robot0_geom_right_E0_viz" pos="0.055 0.15 -0.01" type="mesh" contype="0" conaffinity="0" group="1" margin="0.001" material="robot0_black" mesh="robot0_mesh_right_E0_viz"/>
              <body name="robot0_link_right_W0" pos="0 0 0">
                <inertial pos="0.000229308 0.0158433 -0.154481" mass="0.64434" diaginertia="0.001 0.001 0.001"/>
                <joint name="robot0_joint_right_W0" pos="0 0 0" axis="0 0 1" range="-1.5708 1.5708" armature="0.01" frictionloss="0.1"/>
                <geom name="robot0_geom_right_W0_viz" pos="0.05 0.15 0" type="mesh" contype="0" conaffinity="0" group="1" margin="0.001" material="robot0_black" mesh="robot0_mesh_right_W0_viz"/>
                <body name="robot0_link_right_W1" pos="0 -0.005 -0.1478">
                  <inertial pos="0 0 0" mass="1e-09" diaginertia="1e-09 1e-09 1e-09"/>
                  <joint name="robot0_joint_right_W1" pos="0 0 0" axis="0 1 0" range="-1.5708 1.5708" armature="0.01" frictionloss="0.1"/>
                  <body name="robot0_link_right_W2" pos="0 0 0">
                    <inertial pos="5.4498e-05 0.000382544 -0.0372594" mass="0.145" diaginertia="0.001 0.0004628 0.001"/>
                    <geom name="robot0_geom_right_W2_viz" quat="0 0 0.707107 -0.707107" type="mesh" contype="0" conaffinity="0" group="1" margin="0.001" material="robot0_metal" mesh="robot0_mesh_right_W2_viz"/>
                    <body name="robot0_right_eef" pos="0 0 -0.053" quat="0 1 0 0">
                      <body name="robot0_right_mount" pos="0 0 0" quat="-0.707107 0 0 0.707107">
                        <body name="gripperright_base" pos="0 0 0">
                          <inertial pos="0 0 0" mass="0.3" diaginertia="0.01 0.01 0.01"/>
                          <geom name="gripperright_geom_base_viz" quat="0 0.707107 0 0.707107" type="mesh" group="1" material="gripperright_black" mesh="gripperright_mesh_palm_dual"/>
                          <geom name="gripperright_geom_base_col" size="0.015 0.04 0.038" pos="0 0 0.042" type="box" rgba="0 0 0.5 0"/>
                          <site name="gripperright_site_left_finger1" pos="0 0.03 0" size="0.01" material="gripperright_tendon_site"/>
                          <site name="gripperright_site_left_finger2" pos="0 0.03 0.062569" size="0.01" material="gripperright_tendon_site"/>
                          <site name="gripperright_site_right_finger1" pos="0 -0.03 0" size="0.01" material="gripperright_tendon_site"/>
                          <site name="gripperright_site_right_finger2" pos="0 -0.03 0.062569" size="0.01" material="gripperright_tendon_site"/>
                          <body name="gripperright_left_finger1" pos="0 0.03 0.072569" quat="-0.5 0.5 0.5 0.5">
                            <inertial pos="0 0 0" mass="0.025" diaginertia="0.01 0.01 0.01"/>
                            <joint name="gripperright_joint_left_driver" pos="0 0 0" axis="0 1 0" solreflimit="0.005 1" solimplimit="0.95 0.99 0.001 0.5 2" range="-1.94 1.94"/>
                            <geom name="gripperright_geom_left_finger1" type="mesh" group="1" material="gripperright_white" mesh="gripperright_mesh_finger1"/>
                            <geom name="gripperright_geom_left_finger1_pad" size="0.008 0.014 0.001" pos="0.027 0 -0.012" type="box" group="1" material="gripperright_black"/>
                            <geom name="gripperright_geom_left_finger1_pad_col" size="0.008 0.014 0.001" pos="0.027 0 -0.012" type="box" rgba="0 0 0.5 0"/>
                            <site name="gripperright_site_left_finger3" pos="0.042 0 0.01" size="0.01" material="gripperright_tendon_site"/>
                            <body name="gripperright_left_finger2" pos="0.052 0 0">
                              <inertial pos="0 0 0" mass="0.025" diaginertia="0.01 0.01 0.01"/>
                              <joint name="gripperright_joint_left_coupler" pos="0 0 0" axis="0 1 0" solreflimit="0.005 1" solimplimit="0.95 0.99 0.001 0.5 2" stiffness="0.4" range="0 1.94" frictionloss="0.1"/>
                              <geom name="gripperright_geom_left_finger2" type="mesh" group="1" material="gripperright_white" mesh="gripperright_mesh_finger2"/>
                              <geom name="gripperright_geom_left_finger2_pad" size="0.02 0.014 0.001" pos="0.04 0 0.002" quat="0.983844 0 -0.17903 0" type="box" group="1" material="gripperright_black"/>
                              <geom name="gripperright_geom_left_finger2_pad_col" size="0.02 0.014 0.001" pos="0.04 0 0.002" quat="0.983844 0 -0.17903 0" type="box" rgba="0 0 0.5 0"/>
                              <site name="gripperright_site_left_finger4" pos="0.05 0 0.01" size="0.01" material="gripperright_tendon_site"/>
                            </body>
                          </body>
                          <body name="gripperright_right_finger1" pos="0 -0.03 0.072569" quat="0.5 0.5 -0.5 0.5">
                            <inertial pos="0 0 0" mass="0.025" diaginertia="0.01 0.01 0.01"/>
                            <joint name="gripperright_joint_right_driver" pos="0 0 0" axis="0 1 0" solreflimit="0.005 1" solimplimit="0.95 0.99 0.001 0.5 2" range="-1.94 1.94"/>
                            <geom name="gripperright_geom_right_finger1" type="mesh" group="1" material="gripperright_white" mesh="gripperright_mesh_finger1"/>
                            <geom name="gripperright_geom_right_finger1_pad" size="0.008 0.014 0.001" pos="0.027 0 -0.012" type="box" group="1" material="gripperright_black"/>
                            <geom name="gripperright_geom_right_finger1_pad_col" size="0.008 0.014 0.001" pos="0.027 0 -0.012" type="box" rgba="0 0 0.5 0"/>
                            <site name="gripperright_site_right_finger3" pos="0.042 0 0.01" size="0.01" material="gripperright_tendon_site"/>
                            <body name="gripperright_right_finger2" pos="0.052 0 0">
                              <inertial pos="0 0 0" mass="0.025" diaginertia="0.01 0.01 0.01"/>
                              <joint name="gripperright_joint_right_coupler" pos="0 0 0" axis="0 1 0" solreflimit="0.005 1" solimplimit="0.95 0.99 0.001 0.5 2" stiffness="0.4" range="0 1.94" frictionloss="0.1"/>
                              <geom name="gripperright_geom_right_finger2" type="mesh" group="1" material="gripperright_white" mesh="gripperright_mesh_finger2"/>
                              <geom name="gripperright_geom_right_finger2_pad" size="0.02 0.014 0.001" pos="0.04 0 0.002" quat="0.983844 0 -0.17903 0" type="box" group="1" material="gripperright_black"/>
                              <geom name="gripperright_geom_right_finger2_pad_col" size="0.02 0.014 0.001" pos="0.04 0 0.002" quat="0.983844 0 -0.17903 0" type="box" rgba="0 0 0.5 0"/>
                              <site name="gripperright_site_right_finger4" pos="0.05 0 0.01" size="0.01" material="gripperright_tendon_site"/>
                            </body>
                          </body>
                          <body name="gripperright_eef" pos="0 0 0.13"/>
                        </body>
                      </body>
                      <body name="robot0_right_hand" pos="0 0 -0.073"/>
                    </body>
                  </body>
                </body>
              </body>
            </body>
          </body>
        </body>
      </body>
      <body name="robot0_link_left_S0" pos="-0.05 0.156 0.2625" quat="0.965926 0.258819 0 0">
        <inertial pos="-0.0270089 -0.0272215 0" quat="0.859485 0.500865 0.0884495 0.0509627" mass="1.02127" diaginertia="0.00304494 0.00199964 0.00195542"/>
        <joint name="robot0_joint_left_S0" pos="0 0 0" axis="0 1 0" range="-2.26893 0.698132" armature="0.01" frictionloss="0.1"/>
        <geom name="robot0_geom_left_S0_viz" pos="0.05 -0.27 -0.15" quat="0.965926 -0.258819 0 0" type="mesh" contype="0" conaffinity="0" group="1" margin="0.001" material="robot0_metal" mesh="robot0_mesh_left_S0_viz"/>
        <body name="robot0_link_left_S1" pos="0 0 0" quat="0.965926 -0.258819 0 0">
          <inertial pos="0.0189446 0.000135529 0.00688183" quat="0.00894532 0.674228 0.00366258 0.73846" mass="0.880498" diaginertia="0.00225176 0.00190046 0.00103185"/>
          <joint name="robot0_joint_left_S1" pos="0 0 0" axis="1 0 0" range="0 2.0944" armature="0.01" frictionloss="0.1"/>
          <geom name="robot0_geom_left_S1_viz" type="mesh" contype="0" conaffinity="0" group="1" margin="0.001" material="robot0_black" mesh="robot0_mesh_left_S1_viz"/>
          <body name="robot0_link_left_S2" pos="0 0 0">
            <inertial pos="-0.00401807 0.0300008 -0.137263" mass="1.21235" diaginertia="0.00490878 0.00459797 0.00207282"/>
            <joint name="robot0_joint_left_S2" pos="0 0 0" axis="0 0 1" range="-1.48353 1.48353" armature="0.01" frictionloss="0.1"/>
            <geom name="robot0_geom_left_S2_viz" pos="0.05 -0.15 -0.26" type="mesh" contype="0" conaffinity="0" group="1" margin="0.001" material="robot0_metal" mesh="robot0_mesh_left_S2_viz"/>
            <body name="robot0_link_left_E0" pos="0 0 -0.25">
              <inertial pos="-0.0190443 0 -0.0633779" quat="0.663353 0.244703 0.24453 0.663542" mass="0.989887" diaginertia="0.00297439 0.00246882 0.00183915"/>
              <joint name="robot0_joint_left_E0" pos="0 0 0" axis="0 1 0" range="-2.0944 0.0872665" armature="0.01" frictionloss="0.1"/>
              <geom name="robot0_geom_left_E0_viz" pos="0.055 -0.15 -0.01" type="mesh" contype="0" conaffinity="0" group="1" margin="0.001" material="robot0_black" mesh="robot0_mesh_left_E0_viz"/>
              <body name="robot0_link_left_W0" pos="0 0 0">
                <inertial pos="0.000433726 0.0158433 -0.154" mass="0.64434" diaginertia="0.001 0.001 0.001"/>
                <joint name="robot0_joint_left_W0" pos="0 0 0" axis="0 0 1" range="-1.5708 1.5708" armature="0.01" frictionloss="0.1"/>
                <geom name="robot0_geom_left_W0_viz" pos="0.05 -0.15 0" type="mesh" contype="0" conaffinity="0" group="1" margin="0.001" material="robot0_black" mesh="robot0_mesh_left_W0_viz"/>
                <body name="robot0_link_left_W1" pos="0 0.005 -0.1478">
                  <inertial pos="0 0 0" mass="1e-09" diaginertia="1e-09 1e-09 1e-09"/>
                  <joint name="robot0_joint_left_W1" pos="0 0 0" axis="0 1 0" range="-1.5708 1.5708" armature="0.01" frictionloss="0.1"/>
                  <body name="robot0_link_left_W2" pos="0 0 0">
                    <inertial pos="5.4498e-05 0.000382544 -0.0372594" mass="0.145" diaginertia="0.001 0.0004628 0.001"/>
                    <geom name="robot0_geom_left_W2_viz" quat="0 0 0.707107 -0.707107" type="mesh" contype="0" conaffinity="0" group="1" margin="0.001" material="robot0_metal" mesh="robot0_mesh_left_W2_viz"/>
                    <body name="robot0_left_eef" pos="0 0 -0.053" quat="0 1 0 0">
                      <body name="robot0_left_mount" pos="0 0 0" quat="0.707107 0 0 0.707107">
                        <body name="gripperleft_base" pos="0 0 0">
                          <inertial pos="0 0 0" mass="0.3" diaginertia="0.01 0.01 0.01"/>
                          <geom name="gripperleft_geom_base_viz" quat="0 0.707107 0 0.707107" type="mesh" group="1" material="gripperleft_black" mesh="gripperleft_mesh_palm_dual"/>
                          <geom name="gripperleft_geom_base_col" size="0.015 0.04 0.038" pos="0 0 0.042" type="box" rgba="0 0 0.5 0"/>
                          <site name="gripperleft_site_left_finger1" pos="0 0.03 0" size="0.01" material="gripperleft_tendon_site"/>
                          <site name="gripperleft_site_left_finger2" pos="0 0.03 0.062569" size="0.01" material="gripperleft_tendon_site"/>
                          <site name="gripperleft_site_right_finger1" pos="0 -0.03 0" size="0.01" material="gripperleft_tendon_site"/>
                          <site name="gripperleft_site_right_finger2" pos="0 -0.03 0.062569" size="0.01" material="gripperleft_tendon_site"/>
                          <body name="gripperleft_left_finger1" pos="0 0.03 0.072569" quat="-0.5 0.5 0.5 0.5">
                            <inertial pos="0 0 0" mass="0.025" diaginertia="0.01 0.01 0.01"/>
                            <joint name="gripperleft_joint_left_driver" pos="0 0 0" axis="0 1 0" solreflimit="0.005 1" solimplimit="0.95 0.99 0.001 0.5 2" range="-1.94 1.94"/>
                            <geom name="gripperleft_geom_left_finger1" type="mesh" group="1" material="gripperleft_white" mesh="gripperleft_mesh_finger1"/>
                            <geom name="gripperleft_geom_left_finger1_pad" size="0.008 0.014 0.001" pos="0.027 0 -0.012" type="box" group="1" material="gripperleft_black"/>
                            <geom name="gripperleft_geom_left_finger1_pad_col" size="0.008 0.014 0.001" pos="0.027 0 -0.012" type="box" rgba="0 0 0.5 0"/>
                            <site name="gripperleft_site_left_finger3" pos="0.042 0 0.01" size="0.01" material="gripperleft_tendon_site"/>
                            <body name="gripperleft_left_finger2" pos="0.052 0 0">
                              <inertial pos="0 0 0" mass="0.025" diaginertia="0.01 0.01 0.01"/>
                              <joint name="gripperleft_joint_left_coupler" pos="0 0 0" axis="0 1 0" solreflimit="0.005 1" solimplimit="0.95 0.99 0.001 0.5 2" stiffness="0.4" range="0 1.94" frictionloss="0.1"/>
                              <geom name="gripperleft_geom_left_finger2" type="mesh" group="1" material="gripperleft_white" mesh="gripperleft_mesh_finger2"/>
                              <geom name="gripperleft_geom_left_finger2_pad" size="0.02 0.014 0.001" pos="0.04 0 0.002" quat="0.983844 0 -0.17903 0" type="box" group="1" material="gripperleft_black"/>
                              <geom name="gripperleft_geom_left_finger2_pad_col" size="0.02 0.014 0.001" pos="0.04 0 0.002" quat="0.983844 0 -0.17903 0" type="box" rgba="0 0 0.5 0"/>
                              <site name="gripperleft_site_left_finger4" pos="0.05 0 0.01" size="0.01" material="gripperleft_tendon_site"/>
                            </body>
                          </body>
                          <body name="gripperleft_right_finger1" pos="0 -0.03 0.072569" quat="0.5 0.5 -0.5 0.5">
                            <inertial pos="0 0 0" mass="0.025" diaginertia="0.01 0.01 0.01"/>
                            <joint name="gripperleft_joint_right_driver" pos="0 0 0" axis="0 1 0" solreflimit="0.005 1" solimplimit="0.95 0.99 0.001 0.5 2" range="-1.94 1.94"/>
                            <geom name="gripperleft_geom_right_finger1" type="mesh" group="1" material="gripperleft_white" mesh="gripperleft_mesh_finger1"/>
                            <geom name="gripperleft_geom_right_finger1_pad" size="0.008 0.014 0.001" pos="0.027 0 -0.012" type="box" group="1" material="gripperleft_black"/>
                            <geom name="gripperleft_geom_right_finger1_pad_col" size="0.008 0.014 0.001" pos="0.027 0 -0.012" type="box" rgba="0 0 0.5 0"/>
                            <site name="gripperleft_site_right_finger3" pos="0.042 0 0.01" size="0.01" material="gripperleft_tendon_site"/>
                            <body name="gripperleft_right_finger2" pos="0.052 0 0">
                              <inertial pos="0 0 0" mass="0.025" diaginertia="0.01 0.01 0.01"/>
                              <joint name="gripperleft_joint_right_coupler" pos="0 0 0" axis="0 1 0" solreflimit="0.005 1" solimplimit="0.95 0.99 0.001 0.5 2" stiffness="0.4" range="0 1.94" frictionloss="0.1"/>
                              <geom name="gripperleft_geom_right_finger2" type="mesh" group="1" material="gripperleft_white" mesh="gripperleft_mesh_finger2"/>
                              <geom name="gripperleft_geom_right_finger2_pad" size="0.02 0.014 0.001" pos="0.04 0 0.002" quat="0.983844 0 -0.17903 0" type="box" group="1" material="gripperleft_black"/>
                              <geom name="gripperleft_geom_right_finger2_pad_col" size="0.02 0.014 0.001" pos="0.04 0 0.002" quat="0.983844 0 -0.17903 0" type="box" rgba="0 0 0.5 0"/>
                              <site name="gripperleft_site_right_finger4" pos="0.05 0 0.01" size="0.01" material="gripperleft_tendon_site"/>
                            </body>
                          </body>
                          <body name="gripperleft_eef" pos="0 0 0.13"/>
                        </body>
                      </body>
                      <body name="robot0_left_hand" pos="0 0 -0.073"/>
                    </body>
                  </body>
                </body>
              </body>
            </body>
          </body>
        </body>
      </body>
      <body name="robot0_link_right_H0" pos="0 -0.06 -0.0893782" quat="0.965926 -0.258819 0 0">
        <inertial pos="-0.00699855 -0.00580214 -0.0245826" quat="0.487991 0.544144 0.501326 0.463081" mass="0.139743" diaginertia="0.000200007 0.000159348 0.000106346"/>
        <joint name="robot0_joint_right_H0" pos="0 0 0" axis="0 0 1" range="-0.872665 0.872665" armature="0.01" frictionloss="0.1"/>
        <geom name="robot0_geom_right_H0_viz" type="mesh" contype="0" conaffinity="0" group="1" margin="0.001" material="robot0_black" mesh="robot0_mesh_right_H0_viz"/>
        <body name="robot0_link_right_H1" pos="0 0 -0.07" quat="0.965926 0.258819 0 0">
          <inertial pos="-0.000513526 -0.0019221 -0.00112805" quat="0.542379 -0.0770349 0.444482 0.70875" mass="0.849423" diaginertia="0.00103608 0.000998669 0.000965246"/>
          <joint name="robot0_joint_right_H1" pos="0 0 0" axis="1 0 0" range="-0.785398 0.261799" armature="0.01" frictionloss="0.1"/>
          <geom name="robot0_geom_right_H1_viz" pos="0 0.1 0.15" type="mesh" contype="0" conaffinity="0" group="1" margin="0.001" material="robot0_metal" mesh="robot0_mesh_right_H1_viz"/>
          <body name="robot0_link_right_H2" pos="0 0 0">
            <inertial pos="0.00121565 -0.000254558 -0.171535" quat="0.682552 -0.0364854 0.0222438 0.729587" mass="4.983" diaginertia="0.0633584 0.0569948 0.0146468"/>
            <joint name="robot0_joint_right_H2" pos="0 0 0" axis="0 1 0" range="-1.52716 0.523599" armature="0.01" frictionloss="0.1"/>
            <geom name="robot0_geom_right_H2_viz" pos="0 0.1 0.15" type="mesh" contype="0" conaffinity="0" group="1" margin="0.001" material="robot0_metal" mesh="robot0_mesh_right_H2_viz"/>
            <body name="robot0_link_right_N0" pos="0 0 -0.324231">
              <inertial pos="4.28378e-09 -0.000374047 -0.0259832" quat="0.983852 0.178985 0 0" mass="0.152083" diaginertia="0.00048051 0.000337747 0.000275005"/>
              <joint name="robot0_joint_right_N0" pos="0 0 0" axis="0 1 0" range="-0.0872665 1.52716" armature="0.01" frictionloss="0.1"/>
              <geom name="robot0_geom_right_N0_viz" pos="0.005 0.1 0.47" quat="0 0 0 1" type="mesh" contype="0" conaffinity="0" group="1" margin="0.001" material="robot0_black" mesh="robot0_mesh_left_N0_viz"/>
              <body name="robot0_link_right_N1" pos="0 0 -0.0557693">
                <inertial pos="0 -0.006 -0.0323676" mass="0.090042" diaginertia="0.000230283 7.20839e-05 0.000195694"/>
                <geom name="robot0_geom_right_N1_viz" type="mesh" contype="0" conaffinity="0" group="1" margin="0.001" material="robot0_metal" mesh="robot0_mesh_right_N1_viz"/>
              </body>
              <body name="robot0_link_right_N2" pos="0 0 -0.111539">
                <inertial pos="0.00392246 -0.00238405 -0.07941" quat="0.658627 -0.0485076 0.0383458 0.749925" mass="2.55664" diaginertia="0.0131589 0.0109673 0.00487387"/>
                <joint name="robot0_joint_right_N2" pos="0 0 0" axis="0 1 0" range="-0.0872665 1.52716" armature="0.01" frictionloss="0.1"/>
                <geom name="robot0_geom_right_N2_viz" pos="0 0.1 0.59" type="mesh" contype="0" conaffinity="0" group="1" margin="0.001" material="robot0_black" mesh="robot0_mesh_right_N2_viz"/>
                <body name="robot0_link_right_A0" pos="0 -0.00599 -0.248231">
                  <inertial pos="2.67715e-05 -0.0277455 -0.000699218" quat="0.456344 0.453336 -0.544961 0.537823" mass="0.183143" diaginertia="0.000102001 8.86825e-05 5.8106e-05"/>
                  <joint name="robot0_joint_right_A0" pos="0 0 0" axis="0 1 0" range="-1.5708 1.0472" armature="0.01" frictionloss="0.1"/>
                  <geom name="robot0_geom_right_A0_viz" pos="0 0.105 0.83" type="mesh" contype="0" conaffinity="0" group="1" margin="0.001" material="robot0_metal" mesh="robot0_mesh_right_A0_viz"/>
                  <body name="robot0_link_right_A1" pos="0 0 0">
                    <inertial pos="-0.00320518 0.0068186 -0.0444808" quat="0.397638 0.578781 0.678086 0.217014" mass="0.436553" diaginertia="0.00171546 0.00112271 0.000865932"/>
                    <joint name="robot0_joint_right_A1" pos="0 0 0" axis="1 0 0" range="-0.261799 0.785398" armature="0.01" frictionloss="0.1"/>
                    <geom name="robot0_geom_right_A1_viz" pos="0.01 0.11 0.835" type="mesh" contype="0" conaffinity="0" group="1" margin="0.001" material="robot0_metal" mesh="robot0_mesh_right_A1_viz"/>
                    <geom name="robot0_geom_right_A1_col" size="0.125 0.075 0.0295" pos="0 0.005 -0.046" type="box" priority="1" friction="1.5 0.005 0.0001" solref="0.004 1" solimp="0.95 0.99 0.001 0.5 2" rgba="0 0.5 0 0"/>
                    <body name="robot0_right_foot" pos="0 0 -0.076"/>
                  </body>
                </body>
              </body>
            </body>
          </body>
        </body>
      </body>
      <body name="robot0_link_left_H0" pos="0 0.06 -0.0893782" quat="0.965926 0.258819 0 0">
        <inertial pos="-0.00699855 0.00580214 -0.0245826" quat="0.463081 0.501326 0.544144 0.487991" mass="0.139743" diaginertia="0.000200007 0.000159348 0.000106346"/>
        <joint name="robot0_joint_left_H0" pos="0 0 0" axis="0 0 1" range="-0.872665 0.872665" armature="0.01" frictionloss="0.1"/>
        <geom name="robot0_geom_left_H0_viz" type="mesh" contype="0" conaffinity="0" group="1" margin="0.001" material="robot0_black" mesh="robot0_mesh_left_H0_viz"/>
        <body name="robot0_link_left_H1" pos="0 0 -0.07" quat="0.965926 -0.258819 0 0">
          <inertial pos="0.00107664 0.00164809 -0.00149004" quat="0.697816 0.44669 -0.0692238 0.555634" mass="0.77975" diaginertia="0.00103475 0.00100133 0.000963916"/>
          <joint name="robot0_joint_left_H1" pos="0 0 0" axis="1 0 0" range="-0.261799 0.785398" armature="0.01" frictionloss="0.1"/>
          <geom name="robot0_geom_left_H1_viz" pos="0 -0.1 0.15" type="mesh" contype="0" conaffinity="0" group="1" margin="0.001" material="robot0_metal" mesh="robot0_mesh_left_H1_viz"/>
          <body name="robot0_link_left_H2" pos="0 0 0">
            <inertial pos="0.00057 -0.00303734 -0.164021" quat="0.728702 0.0269567 -0.0384259 0.683221" mass="4.549" diaginertia="0.0556875 0.0497855 0.0126187"/>
            <joint name="robot0_joint_left_H2" pos="0 0 0" axis="0 1 0" range="-1.52716 0.523599" armature="0.01" frictionloss="0.1"/>
            <geom name="robot0_geom_left_H2_viz" pos="0 -0.1 0.15" type="mesh" contype="0" conaffinity="0" group="1" margin="0.001" material="robot0_metal" mesh="robot0_mesh_left_H2_viz"/>
            <body name="robot0_link_left_N0" pos="0 0 -0.324231">
              <inertial pos="-4.80156e-09 0.00425279 -0.0291238" quat="0.968572 -0.248732 0 0" mass="0.135683" diaginertia="0.00048051 0.000350412 0.00026234"/>
              <joint name="robot0_joint_left_N0" pos="0 0 0" axis="0 1 0" range="-0.0872665 1.52716" armature="0.01" frictionloss="0.1"/>
              <geom name="robot0_geom_left_N0_viz" pos="0.005 -0.1 0.47" type="mesh" contype="0" conaffinity="0" group="1" margin="0.001" material="robot0_black" mesh="robot0_mesh_left_N0_viz"/>
              <body name="robot0_link_left_N1" pos="0 0 -0.0557693">
                <inertial pos="0 0.006 -0.0323676" mass="0.090042" diaginertia="0.000230283 7.20839e-05 0.000195694"/>
                <geom name="robot0_geom_left_N1_viz" type="mesh" contype="0" conaffinity="0" group="1" margin="0.001" material="robot0_metal" mesh="robot0_mesh_left_N1_viz"/>
              </body>
              <body name="robot0_link_left_N2" pos="0 0 -0.111539">
                <inertial pos="0.00392246 0.00238405 -0.07941" quat="0.658627 0.0485076 -0.0383458 0.749925" mass="2.55664" diaginertia="0.0131589 0.0109673 0.00487387"/>
                <joint name="robot0_joint_left_N2" pos="0 0 0" axis="0 1 0" range="-0.0872665 1.52716" armature="0.01" frictionloss="0.1"/>
                <geom name="robot0_geom_left_N2_viz" pos="0 -0.1 0.59" type="mesh" contype="0" conaffinity="0" group="1" margin="0.001" material="robot0_black" mesh="robot0_mesh_left_N2_viz"/>
                <body name="robot0_link_left_A0" pos="0 0.006 -0.248231">
                  <inertial pos="2.67715e-05 0.0277455 -0.000699218" quat="0.453336 0.456344 -0.537823 0.544961" mass="0.183143" diaginertia="0.000102001 8.86825e-05 5.8106e-05"/>
                  <joint name="robot0_joint_left_A0" pos="0 0 0" axis="0 1 0" range="-1.5708 1.0472" armature="0.01" frictionloss="0.1"/>
                  <geom name="robot0_geom_left_A0_viz" pos="0 -0.105 0.83" type="mesh" contype="0" conaffinity="0" group="1" margin="0.001" material="robot0_metal" mesh="robot0_mesh_left_A0_viz"/>
                  <body name="robot0_link_left_A1" pos="0 0 0">
                    <inertial pos="-0.00320518 -0.0068186 -0.0444808" quat="0.217014 0.678086 0.578781 0.397638" mass="0.436553" diaginertia="0.00171546 0.00112271 0.000865932"/>
                    <joint name="robot0_joint_left_A1" pos="0 0 0" axis="1 0 0" range="-0.785398 0.261799" armature="0.01" frictionloss="0.1"/>
                    <geom name="robot0_geom_left_A1_viz" pos="0.01 -0.11 0.835" type="mesh" contype="0" conaffinity="0" group="1" margin="0.001" material="robot0_metal" mesh="robot0_mesh_left_A1_viz"/>
                    <geom name="robot0_geom_left_A1_col" size="0.125 0.075 0.0295" pos="0 -0.005 -0.046" type="box" priority="1" friction="1.5 0.005 0.0001" solref="0.004 1" solimp="0.95 0.99 0.001 0.5 2" rgba="0 0.5 0 0"/>
                    <body name="robot0_left_foot" pos="0 0 -0.076"/>
                  </body>
                </body>
              </body>
            </body>
          </body>
        </body>
      </body>
      <body name="robot0_head" pos="-0.0025 0 0.352">
        <inertial pos="0.0133603 -0.00105814 0.0772145" quat="0.415851 0.415215 -0.626401 0.512139" mass="1.22948" diaginertia="0.00281493 0.00229132 0.00190828"/>
        <joint name="robot0_joint_head" pos="0 0 0" axis="0 1 0" range="-0.523599 1.309" armature="0.01" frictionloss="0.1"/>
        <geom name="robot0_geom_head_viz" pos="0 0 -0.35" type="mesh" contype="0" conaffinity="0" group="1" margin="0.001" material="robot0_black" mesh="robot0_mesh_head_viz"/>
        <geom name="robot0_geom_head_col" size="0.05 0.06 0.03" pos="0.02 0 0.085" type="box" margin="0.001" rgba="0 0.5 0 0"/>
        <camera name="robot0_robotright" pos="0.065 0.03 0.1" quat="-0.5 -0.5 0.5 0.5" fovy="120"/>
        <camera name="robot0_robotleft" pos="0.065 -0.03 0.1" quat="-0.5 -0.5 0.5 0.5" fovy="120"/>
        <camera name="robot0_robotview" pos="0.025 0 0" quat="-0.5 -0.5 0.5 0.5" fovy="120"/>
        <camera name="robot0_replayview" pos="0.025 0 0" quat="0.5 -0.5 -0.5 0.5" fovy="120"/>
      </body>
      <camera name="firstview" mode="fixed" target="robot0_head" quat="0.5 -0.5 -0.5 0.5" fovy="120" pos="0.1 0 0.352"/>
    </body>
    <body name="Door_main" pos="2.5 0 0">
      <site name="Door_default_site" pos="0 0 0" size="0.002" rgba="1 0 0 0"/>
      <body pos="0 0 1" quat="0 0 0 1">
        <body name="Door_frame" pos="0 0 0" quat="0.707107 0 0 0.707107">
          <geom name="Door_geom_frame_right_visual" size="0.05 1" pos="0.5 0 0" type="cylinder" contype="0" conaffinity="0" group="1" rgba="0.4 0.4 0.4 1"/>
          <geom name="Door_geom_frame_left_visual" size="0.05 1" pos="-0.5 0 0" type="cylinder" contype="0" conaffinity="0" group="1" rgba="0.4 0.4 0.4 1"/>
          <geom name="Door_geom_latch_female" size="0.02 0.01 0.04" pos="-0.48 0.03 -0.1" type="box" rgba="0 0 0 0"/>
          <body name="Door_door" pos="0 0 0">
            <inertial pos="0 0 0" mass="0.1" diaginertia="0.01 0.015 0.006"/>
            <joint name="Door_hinge" pos="0.5 0 0" axis="0 0 -1" range="0 3" damping="1" frictionloss="1"/>
            <geom name="Door_geom_panel" size="0.45 0.04 0.98" type="box" friction="1 1 1" rgba="0 0 0 0"/>
            <geom name="Door_geom_panel_visual" size="0.45 0.04 0.98" type="box" contype="0" conaffinity="0" group="1" material="Door_MatLightWood"/>
            <body name="Door_latch_male" pos="-0.45 0 -0.1">
              <inertial pos="0 0 -0.005" mass="0.001" diaginertia="0.0001 0.0001 0.0001"/>
              <joint name="Door_joint_latch" pos="0 0 0" axis="1 0 0" type="slide" range="0 0.02"/>
              <geom name="Door_geom_latch_male" size="0.02 0.01" pos="-0.01 0 0" quat="0.707107 0 0.707107 0" type="capsule" friction="1 1 1"/>
              <geom name="Door_geom_latch_male_visual" size="0.02 0.01" pos="-0.01 0 0" quat="0.707107 0 0.707107 0" type="capsule" contype="0" conaffinity="0" group="1" material="Door_MatDark"/>
            </body>
            <body name="Door_handle" pos="-0.35 0 -0.1">
              <inertial pos="-0.017762 0 0" quat="0.365653 0.605347 -0.36522 0.605365" mass="0.1" diaginertia="0.0483771 0.0410001 0.0111013"/>
              <joint name="Door_joint_handle" pos="0 0 0" axis="0 1 0" stiffness="1" range="0 1.5708" frictionloss="0.1"/>
              <geom name="Door_geom_handle_base" size="0.025 0.125" quat="0.707107 -0.707107 0 0" type="cylinder"/>
              <geom name="Door_geom_handle_front" size="0.1 0.015 0.02" pos="0.1 -0.1 0" type="box"/>
              <geom name="Door_geom_handle_back" size="0.1 0.015 0.02" pos="0.1 0.1 0" type="box"/>
              <geom name="Door_geom_handle_base_visual" size="0.025 0.125" quat="0.707107 -0.707107 0 0" type="cylinder" contype="0" conaffinity="0" group="1" material="Door_MatBright"/>
              <geom name="Door_geom_handle_front_visual" size="0.1 0.015 0.02" pos="0.1 -0.1 0" type="box" contype="0" conaffinity="0" group="1" material="Door_MatBright"/>
              <geom name="Door_geom_handle_back_visual" size="0.1 0.015 0.02" pos="0.1 0.1 0" type="box" contype="0" conaffinity="0" group="1" material="Door_MatBright"/>
              <site name="Door_handle" pos="0.125 -0.1 0" size="0.02" rgba="0 0 1 0"/>
            </body>
          </body>
        </body>
      </body>
    </body>
    <body name="wall0_main" pos="2.5 -1.5 0">
      <site name="wall0_default_site" pos="0 0 0" size="0.002" rgba="1 0 0 0"/>
      <body pos="0 0 1">
        <geom name="wall0_panel" size="0.05 1 1" quat="0 0 0.707107 0.707107" type="box" friction="1 1 1" rgba="0.5 0 0 0"/>
        <geom name="wall0_panel_visual" size="0.05 1 1" quat="0 0 0.707107 0.707107" type="box" contype="0" conaffinity="0" group="1" friction="1 1 1" mass="1e-08" material="wall0_MatWhiteBricks"/>
      </body>
    </body>
    <body name="wall1_main" pos="2.5 1.5 0">
      <site name="wall1_default_site" pos="0 0 0" size="0.002" rgba="1 0 0 0"/>
      <body pos="0 0 1">
        <geom name="wall1_panel" size="0.05 1 1" quat="0 0 0.707107 0.707107" type="box" friction="1 1 1" rgba="0.5 0 0 0"/>
        <geom name="wall1_panel_visual" size="0.05 1 1" quat="0 0 0.707107 0.707107" type="box" contype="0" conaffinity="0" group="1" friction="1 1 1" mass="1e-08" material="wall1_MatWhiteBricks"/>
      </body>
    </body>
  </worldbody>
  <equality>
    <joint joint1="robot0_joint_right_N0" joint2="robot0_joint_right_N2" polycoef="0 1 0 0 0"/>
    <joint joint1="robot0_joint_left_N0" joint2="robot0_joint_left_N2" polycoef="0 1 0 0 0"/>
    <tendon tendon1="gripperright_tendon_left" tendon2="gripperright_tendon_right" polycoef="0 1 0 0 0" solref="0.005 1" solimp="0.95 0.99 0.001 0.5 2"/>
    <joint joint1="gripperright_joint_right_driver" joint2="gripperright_joint_left_driver" polycoef="0 1 0 0 0" solref="0.005 1" solimp="0.95 0.99 0.001 0.5 2"/>
    <tendon tendon1="gripperleft_tendon_left" tendon2="gripperleft_tendon_right" polycoef="0 1 0 0 0" solref="0.005 1" solimp="0.95 0.99 0.001 0.5 2"/>
    <joint joint1="gripperleft_joint_right_driver" joint2="gripperleft_joint_left_driver" polycoef="0 1 0 0 0" solref="0.005 1" solimp="0.95 0.99 0.001 0.5 2"/>
    <joint joint1="Door_joint_handle" joint2="Door_joint_latch" polycoef="0 26.18 0 0 0" solref="0.005 1" solimp="0.95 0.99 0.001 0.5 2"/>
  </equality>
  <tendon>
    <spatial name="gripperright_tendon_left" range="0 0.5" stiffness="0.4" frictionloss="0.1" springlength="0" material="gripperright_tendon_line" width="0.002">
      <site site="gripperright_site_left_finger1"/>
      <site site="gripperright_site_left_finger2"/>
      <site site="gripperright_site_left_finger3"/>
      <site site="gripperright_site_left_finger4"/>
    </spatial>
    <spatial name="gripperright_tendon_right" range="0 0.5" stiffness="0.4" frictionloss="0.1" springlength="0" material="gripperright_tendon_line" width="0.002">
      <site site="gripperright_site_right_finger1"/>
      <site site="gripperright_site_right_finger2"/>
      <site site="gripperright_site_right_finger3"/>
      <site site="gripperright_site_right_finger4"/>
    </spatial>
    <spatial name="gripperleft_tendon_left" range="0 0.5" stiffness="0.4" frictionloss="0.1" springlength="0" material="gripperleft_tendon_line" width="0.002">
      <site site="gripperleft_site_left_finger1"/>
      <site site="gripperleft_site_left_finger2"/>
      <site site="gripperleft_site_left_finger3"/>
      <site site="gripperleft_site_left_finger4"/>
    </spatial>
    <spatial name="gripperleft_tendon_right" range="0 0.5" stiffness="0.4" frictionloss="0.1" springlength="0" material="gripperleft_tendon_line" width="0.002">
      <site site="gripperleft_site_right_finger1"/>
      <site site="gripperleft_site_right_finger2"/>
      <site site="gripperleft_site_right_finger3"/>
      <site site="gripperleft_site_right_finger4"/>
    </spatial>
  </tendon>
  <actuator>
    <general name="robot0_torque_right_arm_0" joint="robot0_joint_right_S0" ctrlrange="-18 18"/>
    <general name="robot0_torque_right_arm_1" joint="robot0_joint_right_S1" ctrlrange="-18 18"/>
    <general name="robot0_torque_right_arm_2" joint="robot0_joint_right_S2" ctrlrange="-18 18"/>
    <general name="robot0_torque_right_arm_3" joint="robot0_joint_right_E0" ctrlrange="-10 10"/>
    <general name="robot0_torque_right_arm_4" joint="robot0_joint_right_W0" ctrlrange="-12 12"/>
    <general name="robot0_torque_right_arm_5" joint="robot0_joint_right_W1" ctrlrange="-8.8 8.8"/>
    <general name="robot0_torque_left_arm_0" joint="robot0_joint_left_S0" ctrlrange="-18 18"/>
    <general name="robot0_torque_left_arm_1" joint="robot0_joint_left_S1" ctrlrange="-18 18"/>
    <general name="robot0_torque_left_arm_2" joint="robot0_joint_left_S2" ctrlrange="-18 18"/>
    <general name="robot0_torque_left_arm_3" joint="robot0_joint_left_E0" ctrlrange="-10 10"/>
    <general name="robot0_torque_left_arm_4" joint="robot0_joint_left_W0" ctrlrange="-12 12"/>
    <general name="robot0_torque_left_arm_5" joint="robot0_joint_left_W1" ctrlrange="-8.8 8.8"/>
    <general name="robot0_torque_right_leg_0" joint="robot0_joint_right_H0" ctrlrange="-244 244"/>
    <general name="robot0_torque_right_leg_1" joint="robot0_joint_right_H1" ctrlrange="-256 256"/>
    <general name="robot0_torque_right_leg_2" joint="robot0_joint_right_H2" ctrlrange="-259.6 259.6"/>
    <general name="robot0_torque_right_leg_3" joint="robot0_joint_right_N0" ctrlrange="-240.85 240.85"/>
    <general name="robot0_torque_right_leg_4" joint="robot0_joint_right_N2" ctrlrange="-240.85 240.85"/>
    <general name="robot0_torque_right_leg_5" joint="robot0_joint_right_A0" ctrlrange="-244 244"/>
    <general name="robot0_torque_right_leg_6" joint="robot0_joint_right_A1" ctrlrange="-230 230"/>
    <general name="robot0_torque_left_leg_0" joint="robot0_joint_left_H0" ctrlrange="-244 244"/>
    <general name="robot0_torque_left_leg_1" joint="robot0_joint_left_H1" ctrlrange="-256 256"/>
    <general name="robot0_torque_left_leg_2" joint="robot0_joint_left_H2" ctrlrange="-259.6 259.6"/>
    <general name="robot0_torque_left_leg_3" joint="robot0_joint_left_N0" ctrlrange="-240.85 240.85"/>
    <general name="robot0_torque_left_leg_4" joint="robot0_joint_left_N2" ctrlrange="-240.85 240.85"/>
    <general name="robot0_torque_left_leg_5" joint="robot0_joint_left_A0" ctrlrange="-244 244"/>
    <general name="robot0_torque_left_leg_6" joint="robot0_joint_left_A1" ctrlrange="-230 230"/>
    <general name="robot0_torque_head" joint="robot0_joint_head" ctrlrange="-8.8 8.8"/>
    <general name="gripperright_torque_drive" joint="gripperright_joint_left_driver" ctrlrange="-20 20"/>
    <general name="gripperleft_torque_drive" joint="gripperleft_joint_left_driver" ctrlrange="-20 20"/>
  </actuator>
</mujoco>
